<?xml version="1.0" encoding="UTF-8"?>
<testng-results retried="2" ignored="2" total="6" passed="1" failed="1" skipped="0">
  <reporter-output>
  </reporter-output>
  <suite started-at="2024-07-04T01:25:02 IST" name="Suite" finished-at="2024-07-04T01:25:38 IST" duration-ms="35660">
    <groups>
      <group name="sequential">
        <method signature="Login.ValidatelogIn()[pri:1, instance:testCases.Login@1750fbeb]" name="ValidatelogIn" class="testCases.Login"/>
      </group> <!-- sequential -->
    </groups>
    <test started-at="2024-07-04T01:25:02 IST" name="Test1" finished-at="2024-07-04T01:25:38 IST" duration-ms="35660">
      <class name="testCases.Login">
        <test-method is-config="true" signature="beforeSuite()[pri:0, instance:testCases.Login@1750fbeb]" started-at="2024-07-04T01:25:02 IST" name="beforeSuite" finished-at="2024-07-04T01:25:02 IST" duration-ms="233" status="PASS">
          <reporter-output>
          </reporter-output>
        </test-method> <!-- beforeSuite -->
        <test-method is-config="true" signature="beforeTest()[pri:0, instance:testCases.Login@1750fbeb]" started-at="2024-07-04T01:25:02 IST" name="beforeTest" finished-at="2024-07-04T01:25:29 IST" duration-ms="27470" status="PASS">
          <reporter-output>
          </reporter-output>
        </test-method> <!-- beforeTest -->
        <test-method signature="ValidatelogIn()[pri:1, instance:testCases.Login@1750fbeb]" started-at="2024-07-04T01:25:29 IST" name="ValidatelogIn" finished-at="2024-07-04T01:25:37 IST" duration-ms="7630" status="PASS">
          <reporter-output>
          </reporter-output>
        </test-method> <!-- ValidatelogIn -->
        <test-method retried="true" signature="InvalidlogIn()[pri:2, instance:testCases.Login@1750fbeb]" started-at="2024-07-04T01:25:37 IST" name="InvalidlogIn" finished-at="2024-07-04T01:25:37 IST" duration-ms="49" status="SKIP">
          <exception class="java.lang.AssertionError">
            <message>
              <![CDATA[The following asserts failed:
expected [false] but found [true]]]>
            </message>
            <full-stacktrace>
              <![CDATA[java.lang.AssertionError: The following asserts failed:
expected [false] but found [true]
at org.testng.asserts.SoftAssert.assertAll(SoftAssert.java:46)
at org.testng.asserts.SoftAssert.assertAll(SoftAssert.java:30)
at testCases.Login.InvalidlogIn(Login.java:33)
at java.base/jdk.internal.reflect.DirectMethodHandleAccessor.invoke(DirectMethodHandleAccessor.java:103)
at java.base/java.lang.reflect.Method.invoke(Method.java:580)
at org.testng.internal.invokers.MethodInvocationHelper.invokeMethod(MethodInvocationHelper.java:141)
at org.testng.internal.invokers.TestInvoker.invokeMethod(TestInvoker.java:686)
at org.testng.internal.invokers.TestInvoker.invokeTestMethod(TestInvoker.java:230)
at org.testng.internal.invokers.MethodRunner.runInSequence(MethodRunner.java:63)
at org.testng.internal.invokers.TestInvoker$MethodInvocationAgent.invoke(TestInvoker.java:992)
at org.testng.internal.invokers.TestInvoker.invokeTestMethods(TestInvoker.java:203)
at org.testng.internal.invokers.TestMethodWorker.invokeTestMethods(TestMethodWorker.java:154)
at org.testng.internal.invokers.TestMethodWorker.run(TestMethodWorker.java:134)
at java.base/java.util.ArrayList.forEach(ArrayList.java:1597)
at org.testng.TestRunner.privateRun(TestRunner.java:739)
at org.testng.TestRunner.run(TestRunner.java:614)
at org.testng.SuiteRunner.runTest(SuiteRunner.java:421)
at org.testng.SuiteRunner$SuiteWorker.run(SuiteRunner.java:463)
at org.testng.internal.thread.ThreadUtil.lambda$execute$0(ThreadUtil.java:64)
at java.base/java.util.concurrent.FutureTask.run(FutureTask.java:317)
at java.base/java.util.concurrent.ThreadPoolExecutor.runWorker(ThreadPoolExecutor.java:1144)
at java.base/java.util.concurrent.ThreadPoolExecutor$Worker.run(ThreadPoolExecutor.java:642)
at java.base/java.lang.Thread.run(Thread.java:1570)
]]>
            </full-stacktrace>
          </exception> <!-- java.lang.AssertionError -->
          <reporter-output>
          </reporter-output>
        </test-method> <!-- InvalidlogIn -->
        <test-method retried="true" signature="InvalidlogIn()[pri:2, instance:testCases.Login@1750fbeb]" started-at="2024-07-04T01:25:37 IST" name="InvalidlogIn" finished-at="2024-07-04T01:25:37 IST" duration-ms="38" status="SKIP">
          <exception class="java.lang.AssertionError">
            <message>
              <![CDATA[The following asserts failed:
expected [false] but found [true]]]>
            </message>
            <full-stacktrace>
              <![CDATA[java.lang.AssertionError: The following asserts failed:
expected [false] but found [true]
at org.testng.asserts.SoftAssert.assertAll(SoftAssert.java:46)
at org.testng.asserts.SoftAssert.assertAll(SoftAssert.java:30)
at testCases.Login.InvalidlogIn(Login.java:33)
at java.base/jdk.internal.reflect.DirectMethodHandleAccessor.invoke(DirectMethodHandleAccessor.java:103)
at java.base/java.lang.reflect.Method.invoke(Method.java:580)
at org.testng.internal.invokers.MethodInvocationHelper.invokeMethod(MethodInvocationHelper.java:141)
at org.testng.internal.invokers.TestInvoker.invokeMethod(TestInvoker.java:686)
at org.testng.internal.invokers.TestInvoker.retryFailed(TestInvoker.java:269)
at org.testng.internal.invokers.MethodRunner.runInSequence(MethodRunner.java:76)
at org.testng.internal.invokers.TestInvoker$MethodInvocationAgent.invoke(TestInvoker.java:992)
at org.testng.internal.invokers.TestInvoker.invokeTestMethods(TestInvoker.java:203)
at org.testng.internal.invokers.TestMethodWorker.invokeTestMethods(TestMethodWorker.java:154)
at org.testng.internal.invokers.TestMethodWorker.run(TestMethodWorker.java:134)
at java.base/java.util.ArrayList.forEach(ArrayList.java:1597)
at org.testng.TestRunner.privateRun(TestRunner.java:739)
at org.testng.TestRunner.run(TestRunner.java:614)
at org.testng.SuiteRunner.runTest(SuiteRunner.java:421)
at org.testng.SuiteRunner$SuiteWorker.run(SuiteRunner.java:463)
at org.testng.internal.thread.ThreadUtil.lambda$execute$0(ThreadUtil.java:64)
at java.base/java.util.concurrent.FutureTask.run(FutureTask.java:317)
at java.base/java.util.concurrent.ThreadPoolExecutor.runWorker(ThreadPoolExecutor.java:1144)
at java.base/java.util.concurrent.ThreadPoolExecutor$Worker.run(ThreadPoolExecutor.java:642)
at java.base/java.lang.Thread.run(Thread.java:1570)
]]>
            </full-stacktrace>
          </exception> <!-- java.lang.AssertionError -->
          <reporter-output>
          </reporter-output>
        </test-method> <!-- InvalidlogIn -->
        <test-method signature="InvalidlogIn()[pri:2, instance:testCases.Login@1750fbeb]" started-at="2024-07-04T01:25:37 IST" name="InvalidlogIn" finished-at="2024-07-04T01:25:37 IST" duration-ms="45" status="FAIL">
          <exception class="java.lang.AssertionError">
            <message>
              <![CDATA[The following asserts failed:
expected [false] but found [true]]]>
            </message>
            <full-stacktrace>
              <![CDATA[java.lang.AssertionError: The following asserts failed:
expected [false] but found [true]
at org.testng.asserts.SoftAssert.assertAll(SoftAssert.java:46)
at org.testng.asserts.SoftAssert.assertAll(SoftAssert.java:30)
at testCases.Login.InvalidlogIn(Login.java:33)
at java.base/jdk.internal.reflect.DirectMethodHandleAccessor.invoke(DirectMethodHandleAccessor.java:103)
at java.base/java.lang.reflect.Method.invoke(Method.java:580)
at org.testng.internal.invokers.MethodInvocationHelper.invokeMethod(MethodInvocationHelper.java:141)
at org.testng.internal.invokers.TestInvoker.invokeMethod(TestInvoker.java:686)
at org.testng.internal.invokers.TestInvoker.retryFailed(TestInvoker.java:269)
at org.testng.internal.invokers.MethodRunner.runInSequence(MethodRunner.java:76)
at org.testng.internal.invokers.TestInvoker$MethodInvocationAgent.invoke(TestInvoker.java:992)
at org.testng.internal.invokers.TestInvoker.invokeTestMethods(TestInvoker.java:203)
at org.testng.internal.invokers.TestMethodWorker.invokeTestMethods(TestMethodWorker.java:154)
at org.testng.internal.invokers.TestMethodWorker.run(TestMethodWorker.java:134)
at java.base/java.util.ArrayList.forEach(ArrayList.java:1597)
at org.testng.TestRunner.privateRun(TestRunner.java:739)
at org.testng.TestRunner.run(TestRunner.java:614)
at org.testng.SuiteRunner.runTest(SuiteRunner.java:421)
at org.testng.SuiteRunner$SuiteWorker.run(SuiteRunner.java:463)
at org.testng.internal.thread.ThreadUtil.lambda$execute$0(ThreadUtil.java:64)
at java.base/java.util.concurrent.FutureTask.run(FutureTask.java:317)
at java.base/java.util.concurrent.ThreadPoolExecutor.runWorker(ThreadPoolExecutor.java:1144)
at java.base/java.util.concurrent.ThreadPoolExecutor$Worker.run(ThreadPoolExecutor.java:642)
at java.base/java.lang.Thread.run(Thread.java:1570)
]]>
            </full-stacktrace>
          </exception> <!-- java.lang.AssertionError -->
          <reporter-output>
          </reporter-output>
        </test-method> <!-- InvalidlogIn -->
        <test-method is-config="true" signature="afterTest()[pri:0, instance:testCases.Login@1750fbeb]" started-at="2024-07-04T01:25:37 IST" name="afterTest" finished-at="2024-07-04T01:25:38 IST" duration-ms="121" status="PASS">
          <reporter-output>
          </reporter-output>
        </test-method> <!-- afterTest -->
        <test-method is-config="true" signature="afterSuite()[pri:0, instance:testCases.Login@1750fbeb]" started-at="2024-07-04T01:25:38 IST" name="afterSuite" finished-at="2024-07-04T01:25:38 IST" duration-ms="697" status="PASS">
          <reporter-output>
          </reporter-output>
        </test-method> <!-- afterSuite -->
      </class> <!-- testCases.Login -->
    </test> <!-- Test1 -->
  </suite> <!-- Suite -->
</testng-results>
